[2025-04-03 17:40:36] INFO: CSV file 'data.csv' loaded successfully.
[2025-04-03 17:40:36] INFO: Connected to SQLite database 'company.db'.
[2025-04-03 17:40:36] INFO: Schema conflict detected.
[2025-04-03 17:40:38] INFO: Table 'employees' dropped.
[2025-04-03 17:40:38] INFO: Table 'employees' created or confirmed.
[2025-04-03 17:40:38] INFO: Data inserted into table 'employees'.
[2025-04-03 17:40:38] INFO: Retrieved and displayed data from 'employees'.
[2025-04-03 17:40:38] INFO: SQLite connection closed. Script completed successfully.

[2025-04-03 17:40:42] INFO: CSV file 'data.csv' loaded successfully.
[2025-04-03 17:40:42] INFO: Connected to SQLite database 'company.db'.
[2025-04-03 17:40:42] INFO: Schema conflict detected.
[2025-04-03 17:40:43] INFO: User chose to skip table creation and data insertion.
[2025-04-03 17:58:33] INFO: User listed tables in the database.
[2025-04-03 17:58:55] ERROR: SQL query failed: near "exit": syntax error
[2025-04-03 17:59:03] INFO: User chose to exit the chatbot.
[2025-04-03 17:59:03] INFO: SQLite connection closed. Script completed.
[2025-04-03 18:00:09] INFO: CSV file 'data.csv' loaded successfully.
[2025-04-03 18:00:12] INFO: Table 'data' created.
[2025-04-03 18:00:12] INFO: Data inserted into table 'data'.
[2025-04-03 18:00:15] INFO: User listed tables in the database.
[2025-04-03 18:00:20] INFO: User chose to exit the chatbot.
[2025-04-03 18:00:20] INFO: SQLite connection closed. Script completed.
[2025-04-03 18:03:11] INFO: User chose to exit the chatbot.
[2025-04-03 18:03:11] INFO: SQLite connection closed. Script completed.
[2025-04-03 18:03:13] INFO: CSV file 'data.csv' loaded successfully.
[2025-04-03 18:03:13] INFO: Connected to SQLite database 'company.db'.
[2025-04-03 18:03:13] INFO: Schema conflict detected.
[2025-04-03 18:03:15] INFO: Table 'employees' dropped.
[2025-04-03 18:03:15] INFO: Table 'employees' created or confirmed.
[2025-04-03 18:03:15] INFO: Data inserted into table 'employees'.
[2025-04-03 18:03:15] INFO: Retrieved and displayed data from 'employees'.
[2025-04-03 18:03:15] INFO: SQLite connection closed. Script completed successfully.

[2025-04-03 18:04:23] INFO: User listed tables in the database.
[2025-04-03 18:04:26] INFO: User chose to exit the chatbot.
[2025-04-03 18:04:26] INFO: SQLite connection closed. Script completed.
[2025-04-03 18:13:00] ERROR: Traceback (most recent call last):
  File "/Users/prnv15/Desktop/EC530/Hackathon_2-SQL/EC530-SQLapp/Step5.py", line 137, in chatbot_interaction
    generated_sql = generate_sql_using_ai(table_name, schema, user_query)
                    ^^^^^^^^^^^^^^^^^^^^^^^^^^^^^^^^^^^^^^^^^^^^^^^^^^^^^
  File "/Users/prnv15/Desktop/EC530/Hackathon_2-SQL/EC530-SQLapp/Step5.py", line 84, in generate_sql_using_ai
    response = openai.Completion.create(
               ^^^^^^^^^^^^^^^^^^^^^^^^^
  File "/Library/Frameworks/Python.framework/Versions/3.12/lib/python3.12/site-packages/openai/lib/_old_api.py", line 39, in __call__
    raise APIRemovedInV1(symbol=self._symbol)
openai.lib._old_api.APIRemovedInV1: 

You tried to access openai.Completion, but this is no longer supported in openai>=1.0.0 - see the README at https://github.com/openai/openai-python for the API.

You can run `openai migrate` to automatically upgrade your codebase to use the 1.0.0 interface. 

Alternatively, you can pin your installation to the old version, e.g. `pip install openai==0.28`

A detailed migration guide is available here: https://github.com/openai/openai-python/discussions/742


[2025-04-03 18:13:18] INFO: User chose to exit the chatbot.
[2025-04-03 18:13:18] INFO: SQLite connection closed. Script completed.
[2025-04-03 18:14:02] ERROR: Traceback (most recent call last):
  File "/Users/prnv15/Desktop/EC530/Hackathon_2-SQL/EC530-SQLapp/Step5.py", line 137, in chatbot_interaction
    generated_sql = generate_sql_using_ai(table_name, schema, user_query)
                    ^^^^^^^^^^^^^^^^^^^^^^^^^^^^^^^^^^^^^^^^^^^^^^^^^^^^^
  File "/Users/prnv15/Desktop/EC530/Hackathon_2-SQL/EC530-SQLapp/Step5.py", line 84, in generate_sql_using_ai
    response = openai.Completion.create(
               ^^^^^^^^^^^^^^^^^^^^^^^^^
  File "/Library/Frameworks/Python.framework/Versions/3.12/lib/python3.12/site-packages/openai/lib/_old_api.py", line 39, in __call__
    raise APIRemovedInV1(symbol=self._symbol)
openai.lib._old_api.APIRemovedInV1: 

You tried to access openai.Completion, but this is no longer supported in openai>=1.0.0 - see the README at https://github.com/openai/openai-python for the API.

You can run `openai migrate` to automatically upgrade your codebase to use the 1.0.0 interface. 

Alternatively, you can pin your installation to the old version, e.g. `pip install openai==0.28`

A detailed migration guide is available here: https://github.com/openai/openai-python/discussions/742


[2025-04-03 18:14:10] INFO: User chose to exit the chatbot.
[2025-04-03 18:14:10] INFO: SQLite connection closed. Script completed.
[2025-04-03 18:15:32] ERROR: Traceback (most recent call last):
  File "/Users/prnv15/Desktop/EC530/Hackathon_2-SQL/EC530-SQLapp/Step5.py", line 137, in chatbot_interaction
    generated_sql = generate_sql_using_ai(table_name, schema, user_query)
                    ^^^^^^^^^^^^^^^^^^^^^^^^^^^^^^^^^^^^^^^^^^^^^^^^^^^^^
  File "/Users/prnv15/Desktop/EC530/Hackathon_2-SQL/EC530-SQLapp/Step5.py", line 84, in generate_sql_using_ai
    response = openai.Completion.create(
               ^^^^^^^^^^^^^^^^^^^^^^^^^
  File "/Library/Frameworks/Python.framework/Versions/3.12/lib/python3.12/site-packages/openai/lib/_old_api.py", line 39, in __call__
    raise APIRemovedInV1(symbol=self._symbol)
openai.lib._old_api.APIRemovedInV1: 

You tried to access openai.Completion, but this is no longer supported in openai>=1.0.0 - see the README at https://github.com/openai/openai-python for the API.

You can run `openai migrate` to automatically upgrade your codebase to use the 1.0.0 interface. 

Alternatively, you can pin your installation to the old version, e.g. `pip install openai==0.28`

A detailed migration guide is available here: https://github.com/openai/openai-python/discussions/742


[2025-04-03 18:16:13] INFO: User chose to exit the chatbot.
[2025-04-03 18:16:13] INFO: SQLite connection closed. Script completed.
[2025-04-03 18:16:31] ERROR: Traceback (most recent call last):
  File "/Users/prnv15/Desktop/EC530/Hackathon_2-SQL/EC530-SQLapp/Step5.py", line 142, in chatbot_interaction
    generated_sql = generate_sql_using_ai(table_name, schema, user_query)
                    ^^^^^^^^^^^^^^^^^^^^^^^^^^^^^^^^^^^^^^^^^^^^^^^^^^^^^
  File "/Users/prnv15/Desktop/EC530/Hackathon_2-SQL/EC530-SQLapp/Step5.py", line 86, in generate_sql_using_ai
    response = openai.ChatCompletion.create(
               ^^^^^^^^^^^^^^^^^^^^^^^^^^^^^
  File "/Library/Frameworks/Python.framework/Versions/3.12/lib/python3.12/site-packages/openai/lib/_old_api.py", line 39, in __call__
    raise APIRemovedInV1(symbol=self._symbol)
openai.lib._old_api.APIRemovedInV1: 

You tried to access openai.ChatCompletion, but this is no longer supported in openai>=1.0.0 - see the README at https://github.com/openai/openai-python for the API.

You can run `openai migrate` to automatically upgrade your codebase to use the 1.0.0 interface. 

Alternatively, you can pin your installation to the old version, e.g. `pip install openai==0.28`

A detailed migration guide is available here: https://github.com/openai/openai-python/discussions/742


[2025-04-03 18:17:50] INFO: User chose to exit the chatbot.
[2025-04-03 18:17:50] INFO: SQLite connection closed. Script completed.
[2025-04-03 18:17:58] ERROR: Traceback (most recent call last):
  File "/Users/prnv15/Desktop/EC530/Hackathon_2-SQL/EC530-SQLapp/Step5.py", line 142, in chatbot_interaction
    generated_sql = generate_sql_using_ai(table_name, schema, user_query)
                    ^^^^^^^^^^^^^^^^^^^^^^^^^^^^^^^^^^^^^^^^^^^^^^^^^^^^^
  File "/Users/prnv15/Desktop/EC530/Hackathon_2-SQL/EC530-SQLapp/Step5.py", line 86, in generate_sql_using_ai
    response = openai.ChatCompletion.create(
               ^^^^^^^^^^^^^^^^^^^^^^^^^^^^^
  File "/Library/Frameworks/Python.framework/Versions/3.12/lib/python3.12/site-packages/openai/lib/_old_api.py", line 39, in __call__
    raise APIRemovedInV1(symbol=self._symbol)
openai.lib._old_api.APIRemovedInV1: 

You tried to access openai.ChatCompletion, but this is no longer supported in openai>=1.0.0 - see the README at https://github.com/openai/openai-python for the API.

You can run `openai migrate` to automatically upgrade your codebase to use the 1.0.0 interface. 

Alternatively, you can pin your installation to the old version, e.g. `pip install openai==0.28`

A detailed migration guide is available here: https://github.com/openai/openai-python/discussions/742


[2025-04-03 18:19:23] INFO: User chose to exit the chatbot.
[2025-04-03 18:19:23] INFO: SQLite connection closed. Script completed.
[2025-04-03 18:19:30] ERROR: Traceback (most recent call last):
  File "/Users/prnv15/Desktop/EC530/Hackathon_2-SQL/EC530-SQLapp/Step5.py", line 142, in chatbot_interaction
    generated_sql = generate_sql_using_ai(table_name, schema, user_query)
                    ^^^^^^^^^^^^^^^^^^^^^^^^^^^^^^^^^^^^^^^^^^^^^^^^^^^^^
  File "/Users/prnv15/Desktop/EC530/Hackathon_2-SQL/EC530-SQLapp/Step5.py", line 86, in generate_sql_using_ai
    response = openai.chat.completions.create(
               ^^^^^^^^^^^^^^^^^^^^^^^^^^^^^^^
  File "/Library/Frameworks/Python.framework/Versions/3.12/lib/python3.12/site-packages/openai/_utils/_utils.py", line 277, in wrapper
    return func(*args, **kwargs)
           ^^^^^^^^^^^^^^^^^^^^^
  File "/Library/Frameworks/Python.framework/Versions/3.12/lib/python3.12/site-packages/openai/resources/chat/completions.py", line 579, in create
    return self._post(
           ^^^^^^^^^^^
  File "/Library/Frameworks/Python.framework/Versions/3.12/lib/python3.12/site-packages/openai/_base_client.py", line 1240, in post
    return cast(ResponseT, self.request(cast_to, opts, stream=stream, stream_cls=stream_cls))
                           ^^^^^^^^^^^^^^^^^^^^^^^^^^^^^^^^^^^^^^^^^^^^^^^^^^^^^^^^^^^^^^^^^
  File "/Library/Frameworks/Python.framework/Versions/3.12/lib/python3.12/site-packages/openai/_base_client.py", line 921, in request
    return self._request(
           ^^^^^^^^^^^^^^
  File "/Library/Frameworks/Python.framework/Versions/3.12/lib/python3.12/site-packages/openai/_base_client.py", line 1020, in _request
    raise self._make_status_error_from_response(err.response) from None
openai.AuthenticationError: Error code: 401 - {'error': {'message': 'Incorrect API key provided: YOUR_OPE*******_KEY. You can find your API key at https://platform.openai.com/account/api-keys.', 'type': 'invalid_request_error', 'param': None, 'code': 'invalid_api_key'}}

[2025-04-03 18:21:55] INFO: User chose to exit the chatbot.
[2025-04-03 18:21:55] INFO: SQLite connection closed. Script completed.
[2025-04-03 18:22:03] ERROR: Traceback (most recent call last):
  File "/Users/prnv15/Desktop/EC530/Hackathon_2-SQL/EC530-SQLapp/Step5.py", line 142, in chatbot_interaction
    generated_sql = generate_sql_using_ai(table_name, schema, user_query)
                    ^^^^^^^^^^^^^^^^^^^^^^^^^^^^^^^^^^^^^^^^^^^^^^^^^^^^^
  File "/Users/prnv15/Desktop/EC530/Hackathon_2-SQL/EC530-SQLapp/Step5.py", line 86, in generate_sql_using_ai
    response = openai.chat.completions.create(
               ^^^^^^^^^^^^^^^^^^^^^^^^^^^^^^^
  File "/Library/Frameworks/Python.framework/Versions/3.12/lib/python3.12/site-packages/openai/_utils/_utils.py", line 277, in wrapper
    return func(*args, **kwargs)
           ^^^^^^^^^^^^^^^^^^^^^
  File "/Library/Frameworks/Python.framework/Versions/3.12/lib/python3.12/site-packages/openai/resources/chat/completions.py", line 579, in create
    return self._post(
           ^^^^^^^^^^^
  File "/Library/Frameworks/Python.framework/Versions/3.12/lib/python3.12/site-packages/openai/_base_client.py", line 1240, in post
    return cast(ResponseT, self.request(cast_to, opts, stream=stream, stream_cls=stream_cls))
                           ^^^^^^^^^^^^^^^^^^^^^^^^^^^^^^^^^^^^^^^^^^^^^^^^^^^^^^^^^^^^^^^^^
  File "/Library/Frameworks/Python.framework/Versions/3.12/lib/python3.12/site-packages/openai/_base_client.py", line 921, in request
    return self._request(
           ^^^^^^^^^^^^^^
  File "/Library/Frameworks/Python.framework/Versions/3.12/lib/python3.12/site-packages/openai/_base_client.py", line 1020, in _request
    raise self._make_status_error_from_response(err.response) from None
openai.NotFoundError: Error code: 404 - {'error': {'message': 'The model `gpt-4` does not exist or you do not have access to it.', 'type': 'invalid_request_error', 'param': None, 'code': 'model_not_found'}}

[2025-04-03 18:22:39] INFO: User chose to exit the chatbot.
[2025-04-03 18:22:39] INFO: SQLite connection closed. Script completed.
[2025-04-03 18:22:50] ERROR: Traceback (most recent call last):
  File "/Users/prnv15/Desktop/EC530/Hackathon_2-SQL/EC530-SQLapp/Step5.py", line 142, in chatbot_interaction
    generated_sql = generate_sql_using_ai(table_name, schema, user_query)
                    ^^^^^^^^^^^^^^^^^^^^^^^^^^^^^^^^^^^^^^^^^^^^^^^^^^^^^
  File "/Users/prnv15/Desktop/EC530/Hackathon_2-SQL/EC530-SQLapp/Step5.py", line 86, in generate_sql_using_ai
    response = openai.chat.completions.create(
               ^^^^^^^^^^^^^^^^^^^^^^^^^^^^^^^
  File "/Library/Frameworks/Python.framework/Versions/3.12/lib/python3.12/site-packages/openai/_utils/_utils.py", line 277, in wrapper
    return func(*args, **kwargs)
           ^^^^^^^^^^^^^^^^^^^^^
  File "/Library/Frameworks/Python.framework/Versions/3.12/lib/python3.12/site-packages/openai/resources/chat/completions.py", line 579, in create
    return self._post(
           ^^^^^^^^^^^
  File "/Library/Frameworks/Python.framework/Versions/3.12/lib/python3.12/site-packages/openai/_base_client.py", line 1240, in post
    return cast(ResponseT, self.request(cast_to, opts, stream=stream, stream_cls=stream_cls))
                           ^^^^^^^^^^^^^^^^^^^^^^^^^^^^^^^^^^^^^^^^^^^^^^^^^^^^^^^^^^^^^^^^^
  File "/Library/Frameworks/Python.framework/Versions/3.12/lib/python3.12/site-packages/openai/_base_client.py", line 921, in request
    return self._request(
           ^^^^^^^^^^^^^^
  File "/Library/Frameworks/Python.framework/Versions/3.12/lib/python3.12/site-packages/openai/_base_client.py", line 1005, in _request
    return self._retry_request(
           ^^^^^^^^^^^^^^^^^^^^
  File "/Library/Frameworks/Python.framework/Versions/3.12/lib/python3.12/site-packages/openai/_base_client.py", line 1053, in _retry_request
    return self._request(
           ^^^^^^^^^^^^^^
  File "/Library/Frameworks/Python.framework/Versions/3.12/lib/python3.12/site-packages/openai/_base_client.py", line 1005, in _request
    return self._retry_request(
           ^^^^^^^^^^^^^^^^^^^^
  File "/Library/Frameworks/Python.framework/Versions/3.12/lib/python3.12/site-packages/openai/_base_client.py", line 1053, in _retry_request
    return self._request(
           ^^^^^^^^^^^^^^
  File "/Library/Frameworks/Python.framework/Versions/3.12/lib/python3.12/site-packages/openai/_base_client.py", line 1020, in _request
    raise self._make_status_error_from_response(err.response) from None
openai.RateLimitError: Error code: 429 - {'error': {'message': 'You exceeded your current quota, please check your plan and billing details. For more information on this error, read the docs: https://platform.openai.com/docs/guides/error-codes/api-errors.', 'type': 'insufficient_quota', 'param': None, 'code': 'insufficient_quota'}}

[2025-04-03 18:26:04] INFO: User chose to exit the chatbot.
[2025-04-03 18:26:04] INFO: SQLite connection closed. Script completed.
[2025-04-03 18:26:18] ERROR: Traceback (most recent call last):
  File "/Users/prnv15/Desktop/EC530/Hackathon_2-SQL/EC530-SQLapp/Step5.py", line 142, in chatbot_interaction
    generated_sql = generate_sql_using_ai(table_name, schema, user_query)
                    ^^^^^^^^^^^^^^^^^^^^^^^^^^^^^^^^^^^^^^^^^^^^^^^^^^^^^
  File "/Users/prnv15/Desktop/EC530/Hackathon_2-SQL/EC530-SQLapp/Step5.py", line 86, in generate_sql_using_ai
    response = openai.chat.completions.create(
               ^^^^^^^^^^^^^^^^^^^^^^^^^^^^^^^
  File "/Library/Frameworks/Python.framework/Versions/3.12/lib/python3.12/site-packages/openai/_utils/_utils.py", line 277, in wrapper
    return func(*args, **kwargs)
           ^^^^^^^^^^^^^^^^^^^^^
  File "/Library/Frameworks/Python.framework/Versions/3.12/lib/python3.12/site-packages/openai/resources/chat/completions.py", line 579, in create
    return self._post(
           ^^^^^^^^^^^
  File "/Library/Frameworks/Python.framework/Versions/3.12/lib/python3.12/site-packages/openai/_base_client.py", line 1240, in post
    return cast(ResponseT, self.request(cast_to, opts, stream=stream, stream_cls=stream_cls))
                           ^^^^^^^^^^^^^^^^^^^^^^^^^^^^^^^^^^^^^^^^^^^^^^^^^^^^^^^^^^^^^^^^^
  File "/Library/Frameworks/Python.framework/Versions/3.12/lib/python3.12/site-packages/openai/_base_client.py", line 921, in request
    return self._request(
           ^^^^^^^^^^^^^^
  File "/Library/Frameworks/Python.framework/Versions/3.12/lib/python3.12/site-packages/openai/_base_client.py", line 1005, in _request
    return self._retry_request(
           ^^^^^^^^^^^^^^^^^^^^
  File "/Library/Frameworks/Python.framework/Versions/3.12/lib/python3.12/site-packages/openai/_base_client.py", line 1053, in _retry_request
    return self._request(
           ^^^^^^^^^^^^^^
  File "/Library/Frameworks/Python.framework/Versions/3.12/lib/python3.12/site-packages/openai/_base_client.py", line 1005, in _request
    return self._retry_request(
           ^^^^^^^^^^^^^^^^^^^^
  File "/Library/Frameworks/Python.framework/Versions/3.12/lib/python3.12/site-packages/openai/_base_client.py", line 1053, in _retry_request
    return self._request(
           ^^^^^^^^^^^^^^
  File "/Library/Frameworks/Python.framework/Versions/3.12/lib/python3.12/site-packages/openai/_base_client.py", line 1020, in _request
    raise self._make_status_error_from_response(err.response) from None
openai.RateLimitError: Error code: 429 - {'error': {'message': 'You exceeded your current quota, please check your plan and billing details. For more information on this error, read the docs: https://platform.openai.com/docs/guides/error-codes/api-errors.', 'type': 'insufficient_quota', 'param': None, 'code': 'insufficient_quota'}}

[2025-04-03 18:26:26] INFO: User chose to exit the chatbot.
[2025-04-03 18:26:26] INFO: SQLite connection closed. Script completed.
[2025-04-03 18:27:38] ERROR: Traceback (most recent call last):
  File "/Users/prnv15/Desktop/EC530/Hackathon_2-SQL/EC530-SQLapp/Step5.py", line 142, in chatbot_interaction
    generated_sql = generate_sql_using_ai(table_name, schema, user_query)
                    ^^^^^^^^^^^^^^^^^^^^^^^^^^^^^^^^^^^^^^^^^^^^^^^^^^^^^
  File "/Users/prnv15/Desktop/EC530/Hackathon_2-SQL/EC530-SQLapp/Step5.py", line 86, in generate_sql_using_ai
    response = openai.chat.completions.create(
               ^^^^^^^^^^^^^^^^^^^^^^^^^^^^^^^
  File "/Library/Frameworks/Python.framework/Versions/3.12/lib/python3.12/site-packages/openai/_utils/_utils.py", line 277, in wrapper
    return func(*args, **kwargs)
           ^^^^^^^^^^^^^^^^^^^^^
  File "/Library/Frameworks/Python.framework/Versions/3.12/lib/python3.12/site-packages/openai/resources/chat/completions.py", line 579, in create
    return self._post(
           ^^^^^^^^^^^
  File "/Library/Frameworks/Python.framework/Versions/3.12/lib/python3.12/site-packages/openai/_base_client.py", line 1240, in post
    return cast(ResponseT, self.request(cast_to, opts, stream=stream, stream_cls=stream_cls))
                           ^^^^^^^^^^^^^^^^^^^^^^^^^^^^^^^^^^^^^^^^^^^^^^^^^^^^^^^^^^^^^^^^^
  File "/Library/Frameworks/Python.framework/Versions/3.12/lib/python3.12/site-packages/openai/_base_client.py", line 921, in request
    return self._request(
           ^^^^^^^^^^^^^^
  File "/Library/Frameworks/Python.framework/Versions/3.12/lib/python3.12/site-packages/openai/_base_client.py", line 1005, in _request
    return self._retry_request(
           ^^^^^^^^^^^^^^^^^^^^
  File "/Library/Frameworks/Python.framework/Versions/3.12/lib/python3.12/site-packages/openai/_base_client.py", line 1053, in _retry_request
    return self._request(
           ^^^^^^^^^^^^^^
  File "/Library/Frameworks/Python.framework/Versions/3.12/lib/python3.12/site-packages/openai/_base_client.py", line 1005, in _request
    return self._retry_request(
           ^^^^^^^^^^^^^^^^^^^^
  File "/Library/Frameworks/Python.framework/Versions/3.12/lib/python3.12/site-packages/openai/_base_client.py", line 1053, in _retry_request
    return self._request(
           ^^^^^^^^^^^^^^
  File "/Library/Frameworks/Python.framework/Versions/3.12/lib/python3.12/site-packages/openai/_base_client.py", line 1020, in _request
    raise self._make_status_error_from_response(err.response) from None
openai.RateLimitError: Error code: 429 - {'error': {'message': 'You exceeded your current quota, please check your plan and billing details. For more information on this error, read the docs: https://platform.openai.com/docs/guides/error-codes/api-errors.', 'type': 'insufficient_quota', 'param': None, 'code': 'insufficient_quota'}}

[2025-04-03 18:28:16] INFO: User chose to exit the chatbot.
[2025-04-03 18:28:16] INFO: SQLite connection closed. Script completed.
[2025-04-03 18:28:32] ERROR: Traceback (most recent call last):
  File "/Users/prnv15/Desktop/EC530/Hackathon_2-SQL/EC530-SQLapp/Step5.py", line 142, in chatbot_interaction
    generated_sql = generate_sql_using_ai(table_name, schema, user_query)
                    ^^^^^^^^^^^^^^^^^^^^^^^^^^^^^^^^^^^^^^^^^^^^^^^^^^^^^
  File "/Users/prnv15/Desktop/EC530/Hackathon_2-SQL/EC530-SQLapp/Step5.py", line 86, in generate_sql_using_ai
    response = openai.chat.completions.create(
               ^^^^^^^^^^^^^^^^^^^^^^^^^^^^^^^
  File "/Library/Frameworks/Python.framework/Versions/3.12/lib/python3.12/site-packages/openai/_utils/_utils.py", line 277, in wrapper
    return func(*args, **kwargs)
           ^^^^^^^^^^^^^^^^^^^^^
  File "/Library/Frameworks/Python.framework/Versions/3.12/lib/python3.12/site-packages/openai/resources/chat/completions.py", line 579, in create
    return self._post(
           ^^^^^^^^^^^
  File "/Library/Frameworks/Python.framework/Versions/3.12/lib/python3.12/site-packages/openai/_base_client.py", line 1240, in post
    return cast(ResponseT, self.request(cast_to, opts, stream=stream, stream_cls=stream_cls))
                           ^^^^^^^^^^^^^^^^^^^^^^^^^^^^^^^^^^^^^^^^^^^^^^^^^^^^^^^^^^^^^^^^^
  File "/Library/Frameworks/Python.framework/Versions/3.12/lib/python3.12/site-packages/openai/_base_client.py", line 921, in request
    return self._request(
           ^^^^^^^^^^^^^^
  File "/Library/Frameworks/Python.framework/Versions/3.12/lib/python3.12/site-packages/openai/_base_client.py", line 1005, in _request
    return self._retry_request(
           ^^^^^^^^^^^^^^^^^^^^
  File "/Library/Frameworks/Python.framework/Versions/3.12/lib/python3.12/site-packages/openai/_base_client.py", line 1053, in _retry_request
    return self._request(
           ^^^^^^^^^^^^^^
  File "/Library/Frameworks/Python.framework/Versions/3.12/lib/python3.12/site-packages/openai/_base_client.py", line 1005, in _request
    return self._retry_request(
           ^^^^^^^^^^^^^^^^^^^^
  File "/Library/Frameworks/Python.framework/Versions/3.12/lib/python3.12/site-packages/openai/_base_client.py", line 1053, in _retry_request
    return self._request(
           ^^^^^^^^^^^^^^
  File "/Library/Frameworks/Python.framework/Versions/3.12/lib/python3.12/site-packages/openai/_base_client.py", line 1020, in _request
    raise self._make_status_error_from_response(err.response) from None
openai.RateLimitError: Error code: 429 - {'error': {'message': 'You exceeded your current quota, please check your plan and billing details. For more information on this error, read the docs: https://platform.openai.com/docs/guides/error-codes/api-errors.', 'type': 'insufficient_quota', 'param': None, 'code': 'insufficient_quota'}}

[2025-04-03 18:30:44] INFO: User chose to exit the chatbot.
[2025-04-03 18:30:44] INFO: SQLite connection closed. Script completed.
[2025-04-03 18:30:55] ERROR: Traceback (most recent call last):
  File "/Users/prnv15/Desktop/EC530/Hackathon_2-SQL/EC530-SQLapp/Step5.py", line 141, in chatbot_interaction
    generated_sql = generate_sql_using_ai(table_name, schema, user_query)
                    ^^^^^^^^^^^^^^^^^^^^^^^^^^^^^^^^^^^^^^^^^^^^^^^^^^^^^
  File "/Users/prnv15/Desktop/EC530/Hackathon_2-SQL/EC530-SQLapp/Step5.py", line 85, in generate_sql_using_ai
    response = openai.chat.completions.create(
               ^^^^^^^^^^^^^^^^^^^^^^^^^^^^^^^
  File "/Library/Frameworks/Python.framework/Versions/3.12/lib/python3.12/site-packages/openai/_utils/_utils.py", line 277, in wrapper
    return func(*args, **kwargs)
           ^^^^^^^^^^^^^^^^^^^^^
  File "/Library/Frameworks/Python.framework/Versions/3.12/lib/python3.12/site-packages/openai/resources/chat/completions.py", line 579, in create
    return self._post(
           ^^^^^^^^^^^
  File "/Library/Frameworks/Python.framework/Versions/3.12/lib/python3.12/site-packages/openai/_base_client.py", line 1240, in post
    return cast(ResponseT, self.request(cast_to, opts, stream=stream, stream_cls=stream_cls))
                           ^^^^^^^^^^^^^^^^^^^^^^^^^^^^^^^^^^^^^^^^^^^^^^^^^^^^^^^^^^^^^^^^^
  File "/Library/Frameworks/Python.framework/Versions/3.12/lib/python3.12/site-packages/openai/_base_client.py", line 921, in request
    return self._request(
           ^^^^^^^^^^^^^^
  File "/Library/Frameworks/Python.framework/Versions/3.12/lib/python3.12/site-packages/openai/_base_client.py", line 1005, in _request
    return self._retry_request(
           ^^^^^^^^^^^^^^^^^^^^
  File "/Library/Frameworks/Python.framework/Versions/3.12/lib/python3.12/site-packages/openai/_base_client.py", line 1053, in _retry_request
    return self._request(
           ^^^^^^^^^^^^^^
  File "/Library/Frameworks/Python.framework/Versions/3.12/lib/python3.12/site-packages/openai/_base_client.py", line 1005, in _request
    return self._retry_request(
           ^^^^^^^^^^^^^^^^^^^^
  File "/Library/Frameworks/Python.framework/Versions/3.12/lib/python3.12/site-packages/openai/_base_client.py", line 1053, in _retry_request
    return self._request(
           ^^^^^^^^^^^^^^
  File "/Library/Frameworks/Python.framework/Versions/3.12/lib/python3.12/site-packages/openai/_base_client.py", line 1020, in _request
    raise self._make_status_error_from_response(err.response) from None
openai.RateLimitError: Error code: 429 - {'error': {'message': 'You exceeded your current quota, please check your plan and billing details. For more information on this error, read the docs: https://platform.openai.com/docs/guides/error-codes/api-errors.', 'type': 'insufficient_quota', 'param': None, 'code': 'insufficient_quota'}}

[2025-04-03 18:33:53] INFO: User chose to exit the chatbot.
[2025-04-03 18:33:53] INFO: SQLite connection closed. Script completed.
